#include <iostream>
#include <exception>
using namespace std;
class ArrayIndexOutOfBoundsException : public exception {
public:
    const char* what() const throw() {
        return "Array index out of bounds!";
    }
};
int getElement(int* arr, int size, int index) {
    if (index < 0 || index >= size) {
        throw ArrayIndexOutOfBoundsException();
    }
    return arr[index];
}
int main() {
    const int size = 5;
    int arr[size] = {1, 2, 3, 4, 5};
    int index;
    cout << "Enter an index to access (0 to " << size-1 << "): ";
    cin >> index;
    try {
        int element = getElement(arr, size, index);
        cout << "Element at index " << index << " is " << element << endl;
    } catch (const ArrayIndexOutOfBoundsException& e) {
        cerr << "Exception: " << e.what() << endl;
    }
    return 0;
}


OUTPUT:-
Enter an index to access (0 to 4): 4
Element at index 4 is 5
